<?xml version='1.0' encoding='utf-8'?>
<mujoco model="starrobox_cafe">
  <compiler angle="radian" meshdir="assets" autolimits="true"/>

  <visual>
    <global azimuth="135" elevation="-25" />
    <rgba haze="1 1 1 1" />
  </visual>

  <statistic extent="12" center="0 0 2.5" />

  <asset>
    <texture type="2d" colorspace="auto" name="Texture" builtin="gradient" rgb1="0.2 0.3 0.4" rgb2="0.9 0.9 0.9" width="512" height="512" />
    <texture type="2d" colorspace="auto" name="gripper_tex" builtin="flat" rgb1="0.55 0.55 0.55" width="256" height="256" />
    <texture type="2d" colorspace="auto" name="right_Texture" builtin="gradient" rgb1="0.2 0.3 0.4" rgb2="0.9 0.9 0.9" width="512" height="512" />
    <texture type="2d" colorspace="auto" name="right_gripper_tex" builtin="flat" rgb1="0.55 0.55 0.55" width="256" height="256" />
    <texture type="skybox" colorspace="auto" name="texture_6_" builtin="checker" rgb1="0.96 0.96 0.96" rgb2="0.82 0.82 0.82" width="512" height="3072" />
    <texture type="2d" colorspace="auto" name="checker_tex" builtin="checker" mark="edge" rgb1="0.95 0.95 0.95" rgb2="0.78 0.78 0.78" markrgb="0.65 0.65 0.65" width="512" height="512" />
    <texture type="2d" colorspace="auto" name="box_tex" builtin="flat" rgb1="0.839216 0.819608 0.556863" width="256" height="256" />
    <material name="Material" texuniform="true" metallic="0" roughness="1" rgba="0.5 0.5 0.5 1" />
    <material name="gripper_mat" texture="gripper_tex" rgba="0.75 0.75 0.75 1" />
    <material name="right_Material" texuniform="true" metallic="0" roughness="1" rgba="0.5 0.5 0.5 1" />
    <material name="right_gripper_mat" texture="right_gripper_tex" rgba="0.75 0.75 0.75 1" />
    <material name="checker_mat" texture="checker_tex" texuniform="true" texrepeat="8 8" reflectance="0.05" />
    <material name="box_mat" texture="box_tex" rgba="0.7 0.7 0.7 1" />
    <mesh name="left_base_link" file="base_link.STL" />
    <mesh name="left_shoulder_link" file="robots/fairino5_v6/shoulder_link.STL" />
    <mesh name="left_upperarm_link" file="robots/fairino5_v6/upperarm_link.STL" />
    <mesh name="left_forearm_link" file="robots/fairino5_v6/forearm_link.STL" />
    <mesh name="left_wrist1_link" file="robots/fairino5_v6/wrist1_link.STL" />
    <mesh name="left_wrist2_link" file="robots/fairino5_v6/wrist2_link.STL" />
    <mesh name="left_wrist3_link" file="robots/fairino5_v6/wrist3_link.STL" />
    <mesh name="iai_upper_body" file="gripper/iai/upper_body.stl" scale="0.001 0.001 0.001" />
    <mesh name="iai_lower_body" file="gripper/iai/lower_body.stl" scale="0.001 0.001 0.001" />
    <mesh name="iai_left_pinch" file="gripper/iai/left_pinch.stl" scale="0.001 0.001 0.001" />
    <mesh name="iai_right_pinch" file="gripper/iai/right_pinch.stl" scale="0.001 0.001 0.001" />
    <mesh name="iai_cable" file="gripper/iai/cable.stl" scale="0.001 0.001 0.001" />
    <mesh name="iai_side" file="gripper/iai/gripper_side.stl" scale="0.001 0.001 0.001" />
    <mesh name="iai_claw" file="gripper/iai/claw.stl" scale="0.001 0.001 0.001" />
    <mesh name="iai_gripper_cover" file="gripper/iai/gripper_cover.stl" scale="0.001 0.001 0.001" />
    <mesh name="iai_connect_part" file="gripper/iai/connect_part.stl" scale="0.001 0.001 0.001" />
    <mesh name="right_base_link" file="base_link.STL" />
    <mesh name="right_shoulder_link" file="robots/fairino5_v6/shoulder_link.STL" />
    <mesh name="right_upperarm_link" file="robots/fairino5_v6/upperarm_link.STL" />
    <mesh name="right_forearm_link" file="robots/fairino5_v6/forearm_link.STL" />
    <mesh name="right_wrist1_link" file="robots/fairino5_v6/wrist1_link.STL" />
    <mesh name="right_wrist2_link" file="robots/fairino5_v6/wrist2_link.STL" />
    <mesh name="right_wrist3_link" file="robots/fairino5_v6/wrist3_link.STL" />
    <mesh name="right_iai_upper_body" file="gripper/iai/upper_body.stl" scale="0.001 0.001 0.001" />
    <mesh name="right_iai_lower_body" file="gripper/iai/lower_body.stl" scale="0.001 0.001 0.001" />
    <mesh name="right_iai_left_pinch" file="gripper/iai/left_pinch.stl" scale="0.001 0.001 0.001" />
    <mesh name="right_iai_right_pinch" file="gripper/iai/right_pinch.stl" scale="0.001 0.001 0.001" />
    <mesh name="right_iai_cable" file="gripper/iai/cable.stl" scale="0.001 0.001 0.001" />
    <mesh name="right_iai_side" file="gripper/iai/gripper_side.stl" scale="0.001 0.001 0.001" />
    <mesh name="right_iai_claw" file="gripper/iai/claw.stl" scale="0.001 0.001 0.001" />
    <mesh name="right_iai_gripper_cover" file="gripper/iai/gripper_cover.stl" scale="0.001 0.001 0.001" />
    <mesh name="right_iai_connect_part" file="gripper/iai/connect_part.stl" scale="0.001 0.001 0.001" />
    <mesh name="box_mesh" file="box/starrobot_box.stl" scale="0.001 0.001 0.001" />
  </asset>

  <worldbody>
    <geom name="ground" size="0.5 0.5 0.0001" pos="0 0 -0.12" type="plane" contype="0" conaffinity="0" material="checker_mat" />
    <camera name="topdown" pos="0 0.012091 0.106367" fovy="55" />
    <light name="key_light" pos="0 -0.2 0.25" dir="0 0 -1" type="directional" diffuse="1 1 1" specular="0.2 0.2 0.2" />
    <body name="left/fairino5_v6_root_frame" pos="-0.0360868 0.910242 0.8" quat="0.707107 0 0 -0.707107">
      <body name="left/fairino5_v6_body">
        <body name="left/base_link">
          <inertial pos="-0.00031896 -0.00029673 0.042463" quat="-0.270348 -0.648174 0.282295 -0.653523" mass="1.6185" diaginertia="0.00452139 0.00309793 0.00306769" />
          <geom name="left/geom_0_" type="mesh" contype="0" conaffinity="0" group="2" density="0" mesh="left_base_link" />
          <body name="left/shoulder_link">
            <inertial pos="5.0029e-07 -0.0040922 0.14629" quat="0.999588 0.0287044 7.54149e-06 -1.58789e-05" mass="4.3771" diaginertia="0.010731 0.0104154 0.00817191" />
            <joint name="left/j1" pos="0 0 0" axis="0 0 1" range="-3.0543 3.0543" actuatorgravcomp="true" armature="1" damping="10" />
            <geom name="left/geom_1_" type="mesh" contype="0" conaffinity="0" group="2" density="0" mesh="left_shoulder_link" />
            <body name="left/upperarm_link" pos="0 0 0.152" quat="0.707105 0.707108 0 0">
              <inertial pos="-0.2125 -5.7643e-09 0.1346" quat="0.5 0.5 0.5 0.5" mass="14.458" diaginertia="0.4559 0.44974 0.028392" />
              <joint name="left/j2" pos="0 0 0" axis="0 0 1" ref="-0.072" range="-4.6251 1.4835" actuatorgravcomp="true" armature="0.5" damping="10" frictionloss="0.5" />
              <geom name="left/geom_2_" type="mesh" contype="0" conaffinity="0" group="2" density="0" mesh="left_upperarm_link" />
              <body name="left/forearm_link" pos="-0.425 0 0">
                <inertial pos="-0.18793 -8.4503e-07 0.0066357" quat="0.510607 0.489172 0.489196 0.510568" mass="7.6737" diaginertia="0.16971 0.168834 0.00821541" />
                <joint name="left/j3" pos="0 0 0" axis="0 0 1" range="-2.8274 2.8274" actuatorgravcomp="true" armature="0.3" damping="8" frictionloss="0.3" />
                <geom name="left/geom_3_" type="mesh" contype="0" conaffinity="0" group="2" density="0" mesh="left_forearm_link" />
                <body name="left/wrist1_link" pos="-0.39501 0 0">
                  <inertial pos="4.98e-07 -0.003754 0.097155" quat="0.736149 0.676819 -6.33095e-05 7.15237e-05" mass="1.6266" diaginertia="0.00216 0.00199337 0.00154233" />
                  <joint name="left/j4" pos="0 0 0" axis="0 0 1" range="-4.6251 1.4835" actuatorgravcomp="true" armature="0.1" damping="3" frictionloss="0.1" />
                  <geom name="left/geom_4_" type="mesh" contype="0" conaffinity="0" group="2" density="0" mesh="left_wrist1_link" />
                  <body name="left/wrist2_link" pos="0 0 0.1021" quat="0.707105 0.707108 0 0">
                    <inertial pos="-4.5588e-07 0.0038617 0.098257" quat="0.68712 0.726544 0.000128667 -0.000114125" mass="1.5812" diaginertia="0.0020612 0.00195889 0.00144611" />
                    <joint name="left/j5" pos="0 0 0" axis="0 0 1" range="-3.0543 3.0543" actuatorgravcomp="true" armature="0.1" damping="3" frictionloss="0.1" />
                    <geom name="left/geom_5_" type="mesh" group="2" density="0" mesh="left_wrist2_link" />
                    <body name="left/wrist3_link" pos="0 0 0.102" quat="0 0 0.707105 0.707108">
                      <inertial pos="7.7496e-05 1.7751e-05 0.076122" quat="7.93213e-05 0.706804 0.00108234 0.707408" mass="0.52542" diaginertia="0.00041605 0.00027839 0.00027721" />
                      <joint name="left/j6" pos="0 0 0" axis="0 0 1" range="-3.0543 3.0543" actuatorgravcomp="true" armature="0.05" damping="2" frictionloss="0.1" />
                      <geom name="left/geom_6_" type="mesh" group="2" mesh="left_wrist3_link" />
                      <site name="left/link_tcp" pos="0 0 0.102" size="0.001" group="4" rgba="1 0 0 1" />
                      <site name="left/attachment_site" pos="0 0 0.102" size="0.001" group="5" rgba="1 0 0 1" />
                      <body name="gripper/base" pos="0 -8.18396e-08 0.202095" quat="0.707107 0.707107 0 0">
                        <inertial pos="0 0 0.0002" mass="0.6" diaginertia="0.001 0.001 0.001" />
                        <geom name="upper_body" pos="0.000545159 0 0.0021" quat="0 1 0 0" type="mesh" contype="0" conaffinity="0" density="5" material="gripper_mat" mesh="iai_upper_body" />
                        <geom name="lower_body" pos="0 -0.0410198 -0.0147173" quat="0 1 0 0" type="mesh" group="2" material="gripper_mat" mesh="iai_lower_body" />
                        <geom name="cable" pos="0.00559816 -0.0699537 -0.0479794" quat="0.707107 0 0.707107 0" type="mesh" group="2" material="gripper_mat" mesh="iai_cable" />
                        <geom name="right_side" pos="0 -0.0802952 0" quat="1 0 0 0" type="mesh" material="gripper_mat" mesh="iai_side" />
                        <geom name="left_side" pos="-0.0765432 -0.0806754 0" quat="1 0 0 0" type="mesh" material="gripper_mat" mesh="iai_side" />
                        <geom name="cover" pos="0 0.18463 -0.0489517" quat="0 0 0 1" type="mesh" material="gripper_mat" mesh="iai_gripper_cover" />
                        <geom name="connector" pos="0 0.000735604 -0.0340329" quat="0 0 0 1" type="mesh" material="gripper_mat" mesh="iai_connect_part" />
                        <body name="right_pinch">
                          <joint name="right_pinch" pos="0.02 0 0" axis="-1 0 0" type="slide" limited="true" range="-0.015 0.015" actuatorfrclimited="false" actuatorgravcomp="true" armature="0.001" damping="0.2" />
                          <geom name="right_pinch" pos="0.0243746 0.00245222 0.00147149" quat="0 0 0 1" type="mesh" friction="0" density="1" material="gripper_mat" mesh="iai_right_pinch" />
                          <geom name="right_claw" pos="0.00833277 0.0089508 -0.00681747" quat="0 1 0 0" type="mesh" mass="1e-09" material="gripper_mat" mesh="iai_claw" />
                        </body>
                        <body name="left_pinch">
                          <joint name="left_pinch" pos="-0.02 0 0" axis="1 0 0" type="slide" limited="true" range="-0.015 0.015" actuatorfrclimited="false" actuatorgravcomp="true" armature="0.001" damping="0.2" />
                          <geom name="left_pinch" pos="-0.0232227 0.00214457 0.00154222" quat="0 0 0 1" type="mesh" friction="0" density="1" material="gripper_mat" mesh="iai_left_pinch" />
                          <geom name="left_claw" pos="-0.00733679 0.00840771 0.009739" quat="0 0 0 1" type="mesh" mass="1e-09" material="gripper_mat" mesh="iai_claw" />
                        </body>
                      </body>
                    </body>
                  </body>
                </body>
              </body>
            </body>
          </body>
        </body>
      </body>
    </body>
    <body name="right/fairino5_v6_root_frame" pos="1.0348 0.898533 0.8" quat="0.707107 0 0 -0.707107">
      <body name="right/fairino5_v6_body">
        <body name="right/base_link">
          <inertial pos="-0.00031896 -0.00029673 0.042463" quat="-0.270348 -0.648174 0.282295 -0.653523" mass="1.6185" diaginertia="0.00452139 0.00309793 0.00306769" />
          <geom name="right/geom_0_" type="mesh" contype="0" conaffinity="0" group="2" density="0" mesh="right_base_link" />
          <body name="right/shoulder_link">
            <inertial pos="5.0029e-07 -0.0040922 0.14629" quat="0.999588 0.0287044 7.54149e-06 -1.58789e-05" mass="4.3771" diaginertia="0.010731 0.0104154 0.00817191" />
            <joint name="right/j1" pos="0 0 0" axis="0 0 1" range="-3.0543 3.0543" actuatorgravcomp="true" armature="1" damping="10" />
            <geom name="right/geom_1_" type="mesh" contype="0" conaffinity="0" group="2" density="0" mesh="right_shoulder_link" />
            <body name="right/upperarm_link" pos="0 0 0.152" quat="0.707105 0.707108 0 0">
              <inertial pos="-0.2125 -5.7643e-09 0.1346" quat="0.5 0.5 0.5 0.5" mass="14.458" diaginertia="0.4559 0.44974 0.028392" />
              <joint name="right/j2" pos="0 0 0" axis="0 0 1" ref="-0.072" range="-4.6251 1.4835" actuatorgravcomp="true" armature="0.5" damping="10" frictionloss="0.5" />
              <geom name="right/geom_2_" type="mesh" contype="0" conaffinity="0" group="2" density="0" mesh="right_upperarm_link" />
              <body name="right/forearm_link" pos="-0.425 0 0">
                <inertial pos="-0.18793 -8.4503e-07 0.0066357" quat="0.510607 0.489172 0.489196 0.510568" mass="7.6737" diaginertia="0.16971 0.168834 0.00821541" />
                <joint name="right/j3" pos="0 0 0" axis="0 0 1" range="-2.8274 2.8274" actuatorgravcomp="true" armature="0.3" damping="8" frictionloss="0.3" />
                <geom name="right/geom_3_" type="mesh" contype="0" conaffinity="0" group="2" density="0" mesh="right_forearm_link" />
                <body name="right/wrist1_link" pos="-0.39501 0 0">
                  <inertial pos="4.98e-07 -0.003754 0.097155" quat="0.736149 0.676819 -6.33095e-05 7.15237e-05" mass="1.6266" diaginertia="0.00216 0.00199337 0.00154233" />
                  <joint name="right/j4" pos="0 0 0" axis="0 0 1" range="-4.6251 1.4835" actuatorgravcomp="true" armature="0.1" damping="3" frictionloss="0.1" />
                  <geom name="right/geom_4_" type="mesh" contype="0" conaffinity="0" group="2" density="0" mesh="right_wrist1_link" />
                  <body name="right/wrist2_link" pos="0 0 0.1021" quat="0.707105 0.707108 0 0">
                    <inertial pos="-4.5588e-07 0.0038617 0.098257" quat="0.68712 0.726544 0.000128667 -0.000114125" mass="1.5812" diaginertia="0.0020612 0.00195889 0.00144611" />
                    <joint name="right/j5" pos="0 0 0" axis="0 0 1" range="-3.0543 3.0543" actuatorgravcomp="true" armature="0.1" damping="3" frictionloss="0.1" />
                    <geom name="right/geom_5_" type="mesh" group="2" density="0" mesh="right_wrist2_link" />
                    <body name="right/wrist3_link" pos="0 0 0.102" quat="0 0 0.707105 0.707108">
                      <inertial pos="7.7496e-05 1.7751e-05 0.076122" quat="7.93213e-05 0.706804 0.00108234 0.707408" mass="0.52542" diaginertia="0.00041605 0.00027839 0.00027721" />
                      <joint name="right/j6" pos="0 0 0" axis="0 0 1" range="-3.0543 3.0543" actuatorgravcomp="true" armature="0.05" damping="2" frictionloss="0.1" />
                      <geom name="right/geom_6_" type="mesh" group="2" mesh="right_wrist3_link" />
                      <site name="right/link_tcp" pos="0 0 0.102" size="0.001" group="4" rgba="1 0 0 1" />
                      <site name="right/attachment_site" pos="0 0 0.102" size="0.001" group="5" rgba="1 0 0 1" />
                      <body name="right/gripper/base" pos="0 -8.18396e-08 0.202095" quat="0.707107 0.707107 0 0">
                        <inertial pos="0 0 0.0002" mass="0.6" diaginertia="0.001 0.001 0.001" />
                        <geom name="right/upper_body" pos="0.000545159 0 0.0021" quat="0 1 0 0" type="mesh" contype="0" conaffinity="0" density="5" material="right_gripper_mat" mesh="right_iai_upper_body" />
                        <geom name="right/lower_body" pos="0 -0.0410198 -0.0147173" quat="0 1 0 0" type="mesh" group="2" material="right_gripper_mat" mesh="right_iai_lower_body" />
                        <geom name="right/cable" pos="0.00559816 -0.0699537 -0.0479794" quat="0.707107 0 0.707107 0" type="mesh" group="2" material="right_gripper_mat" mesh="right_iai_cable" />
                        <geom name="right/right_side" pos="0 -0.0802952 0" quat="1 0 0 0" type="mesh" material="right_gripper_mat" mesh="right_iai_side" />
                        <geom name="right/left_side" pos="-0.0765432 -0.0806754 0" quat="1 0 0 0" type="mesh" material="right_gripper_mat" mesh="right_iai_side" />
                        <geom name="right/cover" pos="0 0.18463 -0.0489517" quat="0 0 0 1" type="mesh" material="right_gripper_mat" mesh="right_iai_gripper_cover" />
                        <geom name="right/connector" pos="0 0.000735604 -0.0340329" quat="0 0 0 1" type="mesh" material="right_gripper_mat" mesh="right_iai_connect_part" />
                        <body name="right/right_pinch_body">
                          <joint name="right/right_pinch" pos="0.02 0 0" axis="-1 0 0" type="slide" limited="true" range="-0.015 0.015" actuatorfrclimited="false" actuatorgravcomp="true" armature="0.001" damping="0.2" />
                          <geom name="right/right_pinch" pos="0.0243746 0.00245222 0.00147149" quat="0 0 0 1" type="mesh" friction="0" density="1" material="right_gripper_mat" mesh="right_iai_right_pinch" />
                          <geom name="right/right_claw" pos="0.00833277 0.0089508 -0.00681747" quat="0 1 0 0" type="mesh" mass="1e-09" material="right_gripper_mat" mesh="right_iai_claw" />
                        </body>
                        <body name="right/left_pinch_body">
                          <joint name="right/left_pinch" pos="-0.02 0 0" axis="1 0 0" type="slide" limited="true" range="-0.015 0.015" actuatorfrclimited="false" actuatorgravcomp="true" armature="0.001" damping="0.2" />
                          <geom name="right/left_pinch" pos="-0.0232227 0.00214457 0.00154222" quat="0 0 0 1" type="mesh" friction="0" density="1" material="right_gripper_mat" mesh="right_iai_left_pinch" />
                          <geom name="right/left_claw" pos="-0.00733679 0.00840771 0.009739" quat="0 0 0 1" type="mesh" mass="1e-09" material="right_gripper_mat" mesh="right_iai_claw" />
                        </body>
                      </body>
                    </body>
                  </body>
                </body>
              </body>
            </body>
          </body>
        </body>
      </body>
    </body>
    <body name="box/container">
      <geom name="box/container_collision" pos="0 0 0.00454685" quat="1 0 0 0" type="mesh" group="2" material="box_mat" mesh="box_mesh" />
    </body>
  </worldbody>

  <contact>
    <pair geom1="right_side" geom2="right_pinch" name="gripper_pair_1" />
    <pair geom1="left_side" geom2="left_pinch" name="gripper_pair_2" />
    <pair geom1="right/right_side" geom2="right/right_pinch" name="right/gripper_pair_1" />
    <pair geom1="right/left_side" geom2="right/left_pinch" name="right/gripper_pair_2" />
    <exclude name="exclude_1" body1="left/base_link" body2="left/shoulder_link" />
    <exclude name="gripper_exclude_1" body1="gripper/base" body2="right_pinch" />
    <exclude name="gripper_exclude_2" body1="gripper/base" body2="left_pinch" />
    <exclude name="right_exclude_1" body1="right/base_link" body2="right/shoulder_link" />
    <exclude name="right/gripper_exclude_1" body1="right/gripper/base" body2="right/right_pinch_body" />
    <exclude name="right/gripper_exclude_2" body1="right/gripper/base" body2="right/left_pinch_body" />
  </contact>

  <equality>
    <joint name="new_equality" joint1="right_pinch" joint2="left_pinch" polycoef="0 1 0 0 0" />
    <joint name="right/new_equality" joint1="right/right_pinch" joint2="right/left_pinch" polycoef="0 1 0 0 0" />
  </equality>

  <actuator>
    <general name="left/act1" joint="left/j1" ctrlrange="-3.0543 3.0543" dynprm="0 0 0 0 0 0 0 0 0 0" biastype="affine" gainprm="900" biasprm="0 -900 -180" />
    <general name="left/act2" joint="left/j2" ctrlrange="-4.6251 1.4835" dynprm="0 0 0 0 0 0 0 0 0 0" biastype="affine" gainprm="1200" biasprm="0 -1200 -240" />
    <general name="left/act3" joint="left/j3" ctrlrange="-2.8274 2.8274" dynprm="0 0 0 0 0 0 0 0 0 0" biastype="affine" gainprm="1300" biasprm="0 -1300 -260" />
    <general name="left/act4" joint="left/j4" ctrlrange="-4.6251 1.4835" dynprm="0 0 0 0 0 0 0 0 0 0" biastype="affine" gainprm="160" biasprm="0 -160 -35" />
    <general name="left/act5" joint="left/j5" ctrlrange="-3.0543 3.0543" dynprm="0 0 0 0 0 0 0 0 0 0" biastype="affine" gainprm="140" biasprm="0 -140 -30" />
    <general name="left/act6" joint="left/j6" ctrlrange="-3.0543 3.0543" dynprm="0 0 0 0 0 0 0 0 0 0" biastype="affine" gainprm="140" biasprm="0 -140 -30" />
    <general name="left/gripper_actuator" joint="right_pinch" ctrllimited="true" ctrlrange="-0.015 0.015" dynprm="0 0 0 0 0 0 0 0 0 0" biastype="affine" gainprm="5" biasprm="0 -5" />
    <general name="right/act1" joint="right/j1" ctrlrange="-3.0543 3.0543" dynprm="0 0 0 0 0 0 0 0 0 0" biastype="affine" gainprm="900" biasprm="0 -900 -180" />
    <general name="right/act2" joint="right/j2" ctrlrange="-4.6251 1.4835" dynprm="0 0 0 0 0 0 0 0 0 0" biastype="affine" gainprm="1200" biasprm="0 -1200 -240" />
    <general name="right/act3" joint="right/j3" ctrlrange="-2.8274 2.8274" dynprm="0 0 0 0 0 0 0 0 0 0" biastype="affine" gainprm="1300" biasprm="0 -1300 -260" />
    <general name="right/act4" joint="right/j4" ctrlrange="-4.6251 1.4835" dynprm="0 0 0 0 0 0 0 0 0 0" biastype="affine" gainprm="160" biasprm="0 -160 -35" />
    <general name="right/act5" joint="right/j5" ctrlrange="-3.0543 3.0543" dynprm="0 0 0 0 0 0 0 0 0 0" biastype="affine" gainprm="140" biasprm="0 -140 -30" />
    <general name="right/act6" joint="right/j6" ctrlrange="-3.0543 3.0543" dynprm="0 0 0 0 0 0 0 0 0 0" biastype="affine" gainprm="140" biasprm="0 -140 -30" />
    <general name="right/gripper_actuator" joint="right/right_pinch" ctrllimited="true" ctrlrange="-0.015 0.015" dynprm="0 0 0 0 0 0 0 0 0 0" biastype="affine" gainprm="5" biasprm="0 -5" />
  </actuator>

</mujoco>
